<robot name="test_robot">
  <link name="base_link">
    <visual>
       <geometry>
         <box size="0.2 .3 .1"/>
       </geometry>
       <origin xyz="0 0 0.05" rpy="0 0 0" />
       <material name="yellow">
         <color rgba="1 0.5 0 1"/>
       </material>
    </visual>
  </link>
 

  <joint name="joint_base_wheel1" type="continuous">
      <origin xyz="0.1 0.1 0" rpy="0 0 0" />
      <parent link="base_link"/>
      <child link="wheel_1"/>
      <axis xyz="1 0 0"/>
  </joint>

  <link name="wheel_1">
    <visual>
      <geometry>
        <cylinder length="0.05" radius="0.05"/>
      </geometry>
      <origin xyz="0 0 0" rpy="0 1.57 0" />
      <material name="black">
        <color rgba="0 0 0 1"/>
      </material>
    </visual>
  </link>
 
  <joint name="joint_base_wheel2" type="continuous">
      <origin xyz="-0.1 0.1 0" rpy="0 0 0" />
      <parent link="base_link"/>
      <child link="wheel_2"/>
      <axis xyz="1 0 0"/>
  </joint>

  <link name="wheel_2">
    <visual>
      <geometry>
        <cylinder length="0.05" radius="0.05"/>
      </geometry>
      <origin xyz="0 0 0" rpy="0 1.57 0" />
      <material name="black"/>
        <color rgba="0 0 0 1"/>
    </visual>
  </link>
 
  <joint name="joint_base_wheel3" type="continuous">
      <origin xyz="0.1 -0.1 0" rpy="0 0 0" />
      <parent link="base_link"/>
      <child link="wheel_3"/>
      <axis xyz="1 0 0"/>
  </joint>

  <link name="wheel_3">
    <visual>
      <geometry>
        <cylinder length="0.05" radius="0.05"/>
      </geometry>
      <origin xyz="0 0 0" rpy="0 1.57 0" />
      <material name="black"/>
        <color rgba="0 0 0 1"/>
    </visual>
  </link>
 
  <joint name="joint_base_wheel4" type="continuous">
      <origin xyz="-0.1 -0.1 0" rpy="0 0 0" />
      <parent link="base_link"/>
      <child link="wheel_4"/>
      <axis xyz="1 0 0"/>
  </joint>
 
  <link name="wheel_4">
    <visual>
      <geometry>
        <cylinder length="0.05" radius="0.05"/>
      </geometry>
      <origin xyz="0 0 0" rpy="0 1.57 0" />
      <material name="black"/>
        <color rgba="0 0 0 1"/>
    </visual>
  </link>
 

  <link name="kinect_link">
    <visual>
      <origin xyz="0 0 0" rpy="0 0 0"/>
      <geometry>
        <mesh filename="package://mbot_description/meshes/kinect.dae" />
      </geometry>
    </visual>
  </link>

  <joint name="kinect_joint" type="fixed">
    <origin xyz="0 0.1 0.13" rpy="0 0 0"/>
    <parent link="base_link"/>
    <child link="kinect_link"/>
  </joint>
</robot>
